Workbook

Sheet 契約内容請求内訳
B1: 松田病院 ユニフォーム明細
D2: 2026年 | E2: 5 | F2: 月分
A4: 職種 | B4: 商品名 | C4: 品番 | D4: 貸与枚数 | E4: 月額単価 /1人 | F4: 契約コード | G4: 件数 | H4: 金額
A5: 看護師 | B5: 女性上衣 | C5: UQW1058-93 | D5: 5 | E5: 1250 | F5: K-JJ-5 | G5: =COUNTIF(元データ!$H:$H,F5) -> 21 | H5: =E5*G5 -> 26250
D6: 4 | E6: 1110 | F6: K-JJ-4 | G6: =COUNTIF(元データ!$H:$H,F6) -> 0 | H6: =E6*G6 -> 0
D7: 3 | E7: 970 | F7: K-JJ-3 | G7: =COUNTIF(元データ!$H:$H,F7) -> 2 | H7: =E7*G7 -> 1940
D8: 2 | E8: 830 | F8: K-JJ-2 | G8: =COUNTIF(元データ!$H:$H,F8) -> 3 | H8: =E8*G8 -> 2490
D9: 1 | E9: 680 | F9: K-JJ-1 | G9: =COUNTIF(元データ!$H:$H,F9) -> 0 | H9: =E9*G9 -> 0
B10: 男性用スクラブ | C10: UQM1534-93 | D10: 5 | E10: 1250 | F10: K-DS-5 | G10: =COUNTIF(元データ!$H:$H,F10) -> 1 | H10: =E10*G10 -> 1250
D11: 4 | E11: 1110 | F11: K-DS-4 | G11: =COUNTIF(元データ!$H:$H,F11) -> 0 | H11: =E11*G11 -> 0
D12: 3 | E12: 970 | F12: K-DS-3 | G12: =COUNTIF(元データ!$H:$H,F12) -> 0 | H12: =E12*G12 -> 0
D13: 2 | E13: 830 | F13: K-DS-2 | G13: =COUNTIF(元データ!$H:$H,F13) -> 0 | H13: =E13*G13 -> 0
D14: 1 | E14: 680 | F14: K-DS-1 | G14: =COUNTIF(元データ!$H:$H,F14) -> 0 | H14: =E14*G14 -> 0
B15: 男女兼用パンツ | C15: UQM2106-1 | D15: 5 | E15: 1200 | F15: K-P-5 | G15: =COUNTIF(元データ!$I:$I,F15) -> 22 | H15: =E15*G15 -> 26400
D16: 4 | E16: 1070 | F16: K-P-4 | G16: =COUNTIF(元データ!$I:$I,F16) -> 0 | H16: =E16*G16 -> 0
D17: 3 | E17: 940 | F17: K-P-3 | G17: =COUNTIF(元データ!$I:$I,F17) -> 2 | H17: =E17*G17 -> 1880
D18: 2 | E18: 810 | F18: K-P-2 | G18: =COUNTIF(元データ!$I:$I,F18) -> 3 | H18: =E18*G18 -> 2430
D19: 1 | E19: 670 | F19: K-P-1 | G19: =COUNTIF(元データ!$I:$I,F19) -> 0 | H19: =E19*G19 -> 0
A20: 看護助手 | B20: 男女兼用スクラブ | C20: UQM1540-7 | D20: 5 | E20: 1250 | F20: KJ-S-5 | G20: =COUNTIF(元データ!$H:$H,F20) -> 6 | H20: =E20*G20 -> 7500
D21: 4 | E21: 1110 | F21: KJ-S-4 | G21: =COUNTIF(元データ!$H:$H,F21) -> 0 | H21: =E21*G21 -> 0
D22: 3 | E22: 970 | F22: KJ-S-3 | G22: =COUNTIF(元データ!$H:$H,F22) -> 0 | H22: =E22*G22 -> 0
D23: 2 | E23: 830 | F23: KJ-S-2 | G23: =COUNTIF(元データ!$H:$H,F23) -> 0 | H23: =E23*G23 -> 0
D24: 1 | E24: 680 | F24: KJ-S-1 | G24: =COUNTIF(元データ!$H:$H,F24) -> 0 | H24: =E24*G24 -> 0
B25: 男女兼用パンツ | C25: UP17002V-5 | D25: 5 | E25: 1200 | F25: KJ-P-5 | G25: =COUNTIF(元データ!$I:$I,F25) -> 6 | H25: =E25*G25 -> 7200
D26: 4 | E26: 1070 | F26: KJ-P-4 | G26: =COUNTIF(元データ!$I:$I,F26) -> 0 | H26: =E26*G26 -> 0
D27: 3 | E27: 940 | F27: KJ-P-3 | G27: =COUNTIF(元データ!$I:$I,F27) -> 0 | H27: =E27*G27 -> 0
D28: 2 | E28: 810 | F28: KJ-P-2 | G28: =COUNTIF(元データ!$I:$I,F28) -> 0 | H28: =E28*G28 -> 0
D29: 1 | E29: 670 | F29: KJ-P-1 | G29: =COUNTIF(元データ!$I:$I,F29) -> 0 | H29: =E29*G29 -> 0
A30: クラーク | B30: 女性上衣 | C30: UQW1056-593 | D30: 5 | E30: 1250 | F30: CL-J-5 | G30: =COUNTIF(元データ!$H:$H,F30) -> 2 | H30: =E30*G30 -> 2500
D31: 4 | E31: 1110 | F31: CL-J-4 | G31: =COUNTIF(元データ!$H:$H,F31) -> 0 | H31: =E31*G31 -> 0
D32: 3 | E32: 970 | F32: CL-J-3 | G32: =COUNTIF(元データ!$H:$H,F32) -> 2 | H32: =E32*G32 -> 1940
D33: 2 | E33: 830 | F33: CL-J-2 | G33: =COUNTIF(元データ!$H:$H,F33) -> 0 | H33: =E33*G33 -> 0
D34: 1 | E34: 680 | F34: CL-J-1 | G34: =COUNTIF(元データ!$H:$H,F34) -> 0 | H34: =E34*G34 -> 0
B35: 女性パンツ | C35: UQW2037V-5 | D35: 5 | E35: 1200 | F35: CL-P-5 | G35: =COUNTIF(元データ!$I:$I,F35) -> 2 | H35: =E35*G35 -> 2400
D36: 4 | E36: 1070 | F36: CL-P-4 | G36: =COUNTIF(元データ!$I:$I,F36) -> 0 | H36: =E36*G36 -> 0
D37: 3 | E37: 940 | F37: CL-P-3 | G37: =COUNTIF(元データ!$I:$I,F37) -> 2 | H37: =E37*G37 -> 1880
D38: 2 | E38: 810 | F38: CL-P-2 | G38: =COUNTIF(元データ!$I:$I,F38) -> 0 | H38: =E38*G38 -> 0
D39: 1 | E39: 670 | F39: CL-P-1 | G39: =COUNTIF(元データ!$I:$I,F39) -> 0 | H39: =E39*G39 -> 0
A40: 看護 サポーター | B40: 女性上衣 | C40: UQW1049-90 | D40: 5 | E40: 1230 | F40: KS-JJ-5 | G40: =COUNTIF(元データ!$H:$H,F40) -> 0 | H40: =E40*G40 -> 0
D41: 4 | E41: 1100 | F41: KS-JJ-4 | G41: =COUNTIF(元データ!$H:$H,F41) -> 0 | H41: =E41*G41 -> 0
...

Sheet 元データ
B1: 氏名 | C1: ふりがな | D1: 職種 | E1: 性別 | F1: 部署 | G1: 枚数 | H1: 契約コード１ | I1: 契約コード２ | J1: 上衣品番 | K1: 上衣サイズ | L1: 下衣品番 | M1: 下衣サイズ | N1: 股下 | O1: 変更履歴
B2: 氏名 | C2: ふりがな | D2: 職種 | F2: 部署 | G2: 枚数 | J2: 上衣品番 | K2: 上衣サイズ | L2: 下衣品番 | M2: 下衣サイズ | N2: 股下
A3: 37 | B3: 小川 由莉 | C3: おがわ ゆり | D3: MSW | E3: 女 | F3: 地連 | G3: 5 | H3: SF-NS-5 | I3: SF-DP-5 | J3: UZL3210-91 | K3: S | L3: UZL4204-5 | M3: 11 | N3: 70
A4: 38 | B4: 木村 正子 | C4: きむら まさこ | D4: MSW | E4: 女 | F4: 地連 | G4: 5 | H4: SF-NS-5 | I4: SF-DP-5 | J4: UZL3210-91 | K4: S | L4: UZL4204-5 | M4: 13 | N4: 76
A5: 39 | B5: 髙橋 夕起 | C5: たかはし ゆき | D5: MSW | E5: 女 | F5: 地連 | G5: 5 | H5: SF-NS-5 | I5: SF-DP-5 | J5: UZL3210-91 | K5: M | L5: UZL4204-5 | M5: 13 | N5: 70
A6: 20 | B6: 山田 清美 | C6: やまだ きよみ | D6: 看護師 | E6: 女 | F6: 病棟 | G6: 2 | H6: K-JJ-2 | I6: K-P-2 | J6: UQW1058-93 | K6: M | L6: UQM2106-1 | M6: SS | N6: 70
A7: 9 | B7: 鳥山 和香子 | C7: とりやま わかこ | D7: 看護師 | E7: 女 | F7: 病棟 | G7: 3 | J7: UQW1058-93 | K7: LL | L7: UQM2106-1 | M7: M | N7: 68 | O7: 4/30退職
A8: 15 | B8: 奥谷 亜梨沙 | C8: おくたに ありさ | D8: 看護師 | E8: 女 | F8: 病棟 | G8: 3 | H8: K-JJ-3 | I8: K-P-3 | J8: UQW1058-93 | K8: S | L8: UQM2106-1 | M8: S | N8: 70
A9: 17 | B9: 関井 沙弥佳 | C9: せきい さやか | D9: 看護師 | E9: 女 | F9: 病棟 | G9: 3 | H9: K-JJ-3 | I9: K-P-3 | J9: UQW1058-93 | K9: LL | L9: UQM2106-1 | M9: L | N9: 72
A10: 1 | B10: 佐藤 和歌子 | C10: さとう わかこ | D10: 看護師 | E10: 女 | F10: 病棟 | G10: 5 | H10: K-JJ-5 | I10: K-P-5 | J10: UQW1058-93 | K10: L | L10: UQM2106-1 | M10: S | N10: 76
A11: 2 | B11: 半野 香織 | C11: はんの かおり | D11: 看護師 | E11: 女 | F11: 病棟 | G11: 5 | H11: K-JJ-5 | I11: K-P-5 | J11: UQW1058-93 | K11: M | L11: UQM2106-1 | M11: SS | N11: 64
A12: 3 | B12: 深井 真夕子 | C12: ふかい まゆこ | D12: 看護師 | E12: 女 | F12: 病棟 | G12: 5 | H12: K-JJ-5 | I12: K-P-5 | J12: UQW1058-93 | K12: L | L12: UQM2106-1 | M12: M | N12: 66
A13: 4 | B13: 佐光 とし美 | C13: さこう としみ | D13: 看護師 | E13: 女 | F13: 病棟 | G13: 5 | H13: K-JJ-5 | I13: K-P-5 | J13: UQW1058-93 | K13: LL | L13: UQM2106-1 | M13: L | N13: 82
A14: 5 | B14: 中屋 ひとみ | C14: なかや ひとみ | D14: 看護師 | E14: 女 | F14: 病棟 | G14: 5 | H14: K-JJ-5 | I14: K-P-5 | J14: UQW1058-93 | K14: L | L14: UQM2106-1 | M14: SS | N14: 64
A15: 6 | B15: 田井 裕子 | C15: たい ゆうこ | D15: 看護師 | E15: 女 | F15: 病棟 | G15: 5 | H15: K-JJ-5 | I15: K-P-5 | J15: UQW1058-93 | K15: L | L15: UQM2106-1 | M15: M | N15: 70
A16: 7 | B16: 髙橋 千里 | C16: たかはし ちさと | D16: 看護師 | E16: 女 | F16: 病棟 | G16: 5 | H16: K-JJ-5 | I16: K-P-5 | J16: UQW1058-93 | K16: M | L16: UQM2106-1 | M16: S | N16: 70
A17: 8 | B17: 山田 佳子 | C17: やまだ よしこ | D17: 看護師 | E17: 女 | F17: 病棟 | G17: 5 | H17: K-JJ-5 | I17: K-P-5 | J17: UQW1058-93 | K17: LL | L17: UQM2106-1 | M17: L | N17: 70
A18: 10 | B18: 谷口 めぐみ | C18: たにぐち めぐみ | D18: 看護師 | E18: 女 | F18: 病棟 | G18: 5 | H18: K-JJ-5 | I18: K-P-5 | J18: UQW1058-93 | K18: M | L18: UQM2106-1 | M18: SS | N18: 68
A19: 11 | B19: 森田 美紀 | C19: もりた みき | D19: 看護師 | E19: 女 | F19: 病棟 | G19: 5 | H19: K-JJ-5 | I19: K-P-5 | J19: UQW1058-93 | K19: L | L19: UQM2106-1 | M19: S | N19: 68
A20: 12 | B20: 天良 法子 | C20: てんら のりこ | D20: 看護師 | E20: 女 | F20: 病棟 | G20: 5 | H20: K-JJ-5 | I20: K-P-5 | J20: UQW1058-93 | K20: LL | L20: UQM2106-1 | M20: M2/S3 | N20: 70 | O20: パンツ2サイズ選択
A21: 13 | B21: 松木 育子 | C21: まつき いくこ | D21: 看護師 | E21: 女 | F21: 病棟 | G21: 5 | H21: K-JJ-5 | I21: K-P-5 | J21: UQW1058-93 | K21: M | L21: UQM2106-1 | M21: S | N21: 68
A22: 14 | B22: 辻上 麻美 | C22: つじがみ まみ | D22: 看護師 | E22: 女 | F22: 病棟 | G22: 5 | H22: K-JJ-5 | I22: K-P-5 | J22: UQW1058-93 | K22: LL | L22: UQM2106-1 | M22: M | N22: 74
A23: 16 | B23: 野田 美紀 | C23: のだ みき | D23: 看護師 | E23: 女 | F23: 病棟 | G23: 5 | H23: K-JJ-5 | I23: K-P-5 | J23: UQW1058-93 | K23: 5L | L23: UQM2106-1 | M23: 4L | N23: 72
B24: 石田 唯 | C24: いしだ ゆい | D24: 看護師 | E24: 女 | F24: 病棟 | G24: 5 | H24: K-JJ-5 | I24: K-P-5 | J24: UQW1058-93 | K24: S | L24: UQM2106-1 | M24: S | N24: 66 | O24: 5/1入職
B25: 永田 栞 | C25: ながた しおり | D25: 看護師 | E25: 女 | F25: 病棟 | G25: 5 | H25: K-JJ-5 | I25: K-P-5 | J25: UQW1058-93 | K25: S | L25: UQM2106-1 | M25: S | N25: 70 | O25: 5/1入職
B26: 吉塚 由起子 | C26: よしづかゆきこ | D26: 看護師 | E26: 女 | F26: 病棟 | G26: 2 | H26: K-JJ-2 | I26: K-P-2 | J26: UQW1058-93 | K26: LL | L26: UQM2106-1 | M26: L | N26: 70 | O26: 5/1入職
A27: 21 | B27: 山根 朋子 | C27: やまね ともこ | D27: 看護師 | E27: 女 | F27: 外来 | G27: 5 | H27: K-JJ-5 | I27: K-P-5 | J27: UQW1058-93 | K27: LL | L27: UQM2106-1 | M27: S | N27: 68
A28: 22 | B28: 鯰谷 真里 | C28: なまずたに まり | D28: 看護師 | E28: 女 | F28: 外来 | G28: 5 | H28: K-JJ-5 | I28: K-P-5 | J28: UQW1058-93 | K28: S | L28: UQM2106-1 | M28: SS | N28: 68
A29: 23 | B29: 元茂 佳奈 | C29: もとしげ かな | D29: 看護師 | E29: 女 | F29: 外来 | G29: 5 | H29: K-JJ-5 | I29: K-P-5 | J29: UQW1058-93 | K29: L | L29: UQM2106-1 | M29: M | N29: 74
A30: 24 | B30: 徳岡 美佳 | C30: とくおか みか | D30: 看護師 | E30: 女 | F30: 外来 | G30: 5 | H30: K-JJ-5 | I30: K-P-5 | J30: UQW1058-93 | K30: L | L30: UQM2106-1 | M30: SS | N30: 68
A31: 25 | B31: 小畑 幸 | C31: こばた みゆき | D31: 看護師 | E31: 女 | F31: 外来 | G31: 5 | J31: UQW1058-93 | K31: S | L31: UQM2106-1 | M31: SS | N31: 70 | O31: 2月末退職
B32: 田輪 香子 | C32: たわ きょうこ | D32: 看護師 | E32: 女 | F32: 外来 | G32: 5 | H32: K-JJ-5 | I32: K-P-5 | J32: UQW1058-93 | K32: S | L32: UQM2106-1 | M32: M | N32: 70 | O32: 4/1入職
A33: 1 | B33: 中村 和司 | C33: なかむら かずし | D33: 看護師 | E33: 男 | F33: 病棟 | G33: 5 | H33: K-DS-5 | I33: K-P-5 | J33: UQM1534-93 | K33: L | L33: UQM2106-1 | M33: L | N33: 70
A34: 26 | B34: 森川 まり | C34: もりかわ まり | D34: 看護助手 | E34: 女 | F34: 病棟 | G34: 5 | H34: KJ-S-5 | I34: KJ-P-5 | J34: UQM1540-7 | K34: LL | L34: UP17002V-5 | M34: LL | N34: 62
A35: 27 | B35: 海地 由美子 | C35: かいち ゆみこ | D35: 看護助手 | E35: 女 | F35: 病棟 | G35: 5 | H35: KJ-S-5 | I35: KJ-P-5 | J35: UQM1540-7 | K35: M | L35: UP17002V-5 | M35: M | N35: 62
A36: 28 | B36: 宮本 静代 | C36: みやもと しずよ | D36: 看護助手 | E36: 女 | F36: 病棟 | G36: 5 | H36: KJ-S-5 | I36: KJ-P-5 | J36: UQM1540-7 | K36: L | L36: UP17002V-5 | M36: LL | N36: 70
A37: 29 | B37: バヤルマー | C37: ばやるまー | D37: 看護助手 | E37: 女 | F37: 病棟 | G37: 5 | J37: UQM1540-7 | K37: M | L37: UP17002V-5 | M37: M | N37: 70 | O37: 3/24退職
A38: 30 | B38: 小山 房代 | C38: こやま ふさよ | D38: 看護助手 | E38: 女 | F38: 病棟 | G38: 5 | H38: KJ-S-5 | I38: KJ-P-5 | J38: UQM1540-7 | K38: M | L38: UP17002V-5 | M38: M | N38: 68
A39: 2 | B39: 堂下 恭平 | C39: どうした きょうへい | D39: 看護助手 | E39: 男 | F39: 病棟 | G39: 5 | H39: KJ-S-5 | I39: KJ-P-5 | J39: UQM1540-7 | K39: 5L | L39: UP17002V-5 | M39: 4L | N39: 70
A40: 3 | B40: 土井 敦史 | C40: どい あつし | D40: 看護助手 | E40: 男 | F40: 病棟 | G40: 5 | H40: KJ-S-5 | I40: KJ-P-5 | J40: UQM1540-7 | K40: L | L40: UP17002V-5 | M40: L | N40: 76
...
