Workbook

Sheet 請求合計
A1: 在宅ほくと ユニフォーム請求対象人数
B3: 2026年 | C3: 2 | D3: 月分
A4: 契約名 | B4: 職種 | C4: 貸与枚数 | D4: 在宅 | E4: ケアホーム | F4: ケアホームⅡ | G4: シニアホーム | H4: 合計人数 | I4: 単価 | J4: 金額
A5: R0201 | B5: ヘルパーステーション 男女 | C5: 5 | D5: =COUNTIFS(請求詳細!$E:$E,D$4,請求詳細!$F:$F,$A5) -> 0 | E5: =COUNTIFS(請求詳細!$E:$E,E$4,請求詳細!$F:$F,$A5) -> 6 | F5: =COUNTIFS(請求詳細!$E:$E,F$4,請求詳細!$F:$F,$A5) -> 9 | G5: =COUNTIFS(請求詳細!$E:$E,G$4,請求詳細!$F:$F,$A5) -> 17 | H5: =COUNTIF(請求詳細!$F:$F,$A5) -> 32 | I5: 2330 | J5: =H5*I5 -> 74560 | K5: =SUM(D5:G5)-H5 -> 0
A6: R0202 | B6: ヘルパーステーション 男女 | C6: 4 | D6: =COUNTIFS(請求詳細!$E:$E,D$4,請求詳細!$F:$F,$A6) -> 0 | E6: =COUNTIFS(請求詳細!$E:$E,E$4,請求詳細!$F:$F,$A6) -> 1 | F6: =COUNTIFS(請求詳細!$E:$E,F$4,請求詳細!$F:$F,$A6) -> 1 | G6: =COUNTIFS(請求詳細!$E:$E,G$4,請求詳細!$F:$F,$A6) -> 1 | H6: =COUNTIF(請求詳細!$F:$F,$A6) -> 3 | I6: 2110 | J6: =H6*I6 -> 6330 | K6: =SUM(D6:G6)-H6 -> 0
A7: R0203 | B7: ヘルパーステーション 男女 | C7: 3 | D7: =COUNTIFS(請求詳細!$E:$E,D$4,請求詳細!$F:$F,$A7) -> 0 | E7: =COUNTIFS(請求詳細!$E:$E,E$4,請求詳細!$F:$F,$A7) -> 0 | F7: =COUNTIFS(請求詳細!$E:$E,F$4,請求詳細!$F:$F,$A7) -> 0 | G7: =COUNTIFS(請求詳細!$E:$E,G$4,請求詳細!$F:$F,$A7) -> 0 | H7: =COUNTIF(請求詳細!$F:$F,$A7) -> 0 | I7: 2200 | J7: =H7*I7 -> 0 | K7: =SUM(D7:G7)-H7 -> 0
A8: R0204 | B8: ヘルパーステーション 男女 | C8: 2 | D8: =COUNTIFS(請求詳細!$E:$E,D$4,請求詳細!$F:$F,$A8) -> 0 | E8: =COUNTIFS(請求詳細!$E:$E,E$4,請求詳細!$F:$F,$A8) -> 0 | F8: =COUNTIFS(請求詳細!$E:$E,F$4,請求詳細!$F:$F,$A8) -> 0 | G8: =COUNTIFS(請求詳細!$E:$E,G$4,請求詳細!$F:$F,$A8) -> 0 | H8: =COUNTIF(請求詳細!$F:$F,$A8) -> 0 | I8: 1670 | J8: =H8*I8 -> 0 | K8: =SUM(D8:G8)-H8 -> 0
A9: R0211 | B9: ヘルパーステーション （サ責）男女 | C9: 5 | D9: =COUNTIFS(請求詳細!$E:$E,D$4,請求詳細!$F:$F,$A9) -> 4 | E9: =COUNTIFS(請求詳細!$E:$E,E$4,請求詳細!$F:$F,$A9) -> 2 | F9: =COUNTIFS(請求詳細!$E:$E,F$4,請求詳細!$F:$F,$A9) -> 4 | G9: =COUNTIFS(請求詳細!$E:$E,G$4,請求詳細!$F:$F,$A9) -> 6 | H9: =COUNTIF(請求詳細!$F:$F,$A9) -> 16 | I9: 2330 | J9: =H9*I9 -> 37280 | K9: =SUM(D9:G9)-H9 -> 0
A10: R0212 | B10: ヘルパーステーション （サ責）男女 | C10: 4 | D10: =COUNTIFS(請求詳細!$E:$E,D$4,請求詳細!$F:$F,$A10) -> 0 | E10: =COUNTIFS(請求詳細!$E:$E,E$4,請求詳細!$F:$F,$A10) -> 0 | F10: =COUNTIFS(請求詳細!$E:$E,F$4,請求詳細!$F:$F,$A10) -> 0 | G10: =COUNTIFS(請求詳細!$E:$E,G$4,請求詳細!$F:$F,$A10) -> 0 | H10: =COUNTIF(請求詳細!$F:$F,$A10) -> 0 | I10: 2110 | J10: =H10*I10 -> 0 | K10: =SUM(D10:G10)-H10 -> 0
A11: R0213 | B11: ヘルパーステーション （サ責）男女 | C11: 3 | D11: =COUNTIFS(請求詳細!$E:$E,D$4,請求詳細!$F:$F,$A11) -> 0 | E11: =COUNTIFS(請求詳細!$E:$E,E$4,請求詳細!$F:$F,$A11) -> 0 | F11: =COUNTIFS(請求詳細!$E:$E,F$4,請求詳細!$F:$F,$A11) -> 0 | G11: =COUNTIFS(請求詳細!$E:$E,G$4,請求詳細!$F:$F,$A11) -> 0 | H11: =COUNTIF(請求詳細!$F:$F,$A11) -> 0 | I11: 2200 | J11: =H11*I11 -> 0 | K11: =SUM(D11:G11)-H11 -> 0
A12: R0214 | B12: ヘルパーステーション （サ責）男女 | C12: 2 | D12: =COUNTIFS(請求詳細!$E:$E,D$4,請求詳細!$F:$F,$A12) -> 0 | E12: =COUNTIFS(請求詳細!$E:$E,E$4,請求詳細!$F:$F,$A12) -> 0 | F12: =COUNTIFS(請求詳細!$E:$E,F$4,請求詳細!$F:$F,$A12) -> 0 | G12: =COUNTIFS(請求詳細!$E:$E,G$4,請求詳細!$F:$F,$A12) -> 0 | H12: =COUNTIF(請求詳細!$F:$F,$A12) -> 0 | I12: 1670 | J12: =H12*I12 -> 0 | K12: =SUM(D12:G12)-H12 -> 0
A13: R0221 | B13: 訪問看護ステーション （ラポール）女性 | C13: 5 | D13: =COUNTIFS(請求詳細!$E:$E,D$4,請求詳細!$F:$F,$A13) -> 7 | E13: =COUNTIFS(請求詳細!$E:$E,E$4,請求詳細!$F:$F,$A13) -> 7 | F13: =COUNTIFS(請求詳細!$E:$E,F$4,請求詳細!$F:$F,$A13) -> 0 | G13: =COUNTIFS(請求詳細!$E:$E,G$4,請求詳細!$F:$F,$A13) -> 14 | H13: =COUNTIF(請求詳細!$F:$F,$A13) -> 28 | I13: 2420 | J13: =H13*I13 -> 67760 | K13: =SUM(D13:G13)-H13 -> 0
A14: R0222 | B14: 訪問看護ステーション （ラポール）女性 | C14: 4 | D14: =COUNTIFS(請求詳細!$E:$E,D$4,請求詳細!$F:$F,$A14) -> 0 | E14: =COUNTIFS(請求詳細!$E:$E,E$4,請求詳細!$F:$F,$A14) -> 3 | F14: =COUNTIFS(請求詳細!$E:$E,F$4,請求詳細!$F:$F,$A14) -> 0 | G14: =COUNTIFS(請求詳細!$E:$E,G$4,請求詳細!$F:$F,$A14) -> 6 | H14: 4 | I14: 2180 | J14: =H14*I14 -> 8720 | K14: =SUM(D14:G14)-H14 -> 5
A15: R0223 | B15: 訪問看護ステーション （ラポール）女性 | C15: 3 | D15: =COUNTIFS(請求詳細!$E:$E,D$4,請求詳細!$F:$F,$A15) -> 0 | E15: =COUNTIFS(請求詳細!$E:$E,E$4,請求詳細!$F:$F,$A15) -> 0 | F15: =COUNTIFS(請求詳細!$E:$E,F$4,請求詳細!$F:$F,$A15) -> 0 | G15: =COUNTIFS(請求詳細!$E:$E,G$4,請求詳細!$F:$F,$A15) -> 0 | H15: =COUNTIF(請求詳細!$F:$F,$A15) -> 0 | J15: =H15*I15 -> 0 | K15: =SUM(D15:G15)-H15 -> 0
A16: R0224 | B16: 訪問看護ステーション （ラポール）女性 | C16: 2 | D16: =COUNTIFS(請求詳細!$E:$E,D$4,請求詳細!$F:$F,$A16) -> 0 | E16: =COUNTIFS(請求詳細!$E:$E,E$4,請求詳細!$F:$F,$A16) -> 1 | F16: =COUNTIFS(請求詳細!$E:$E,F$4,請求詳細!$F:$F,$A16) -> 0 | G16: =COUNTIFS(請求詳細!$E:$E,G$4,請求詳細!$F:$F,$A16) -> 2 | H16: =COUNTIF(請求詳細!$F:$F,$A16) -> 3 | I16: 1700 | J16: =H16*I16 -> 5100 | K16: =SUM(D16:G16)-H16 -> 0
A17: R0231 | B17: 訪問看護ステーション （ラポール）男性 | C17: 5 | D17: =COUNTIFS(請求詳細!$E:$E,D$4,請求詳細!$F:$F,$A17) -> 0 | E17: =COUNTIFS(請求詳細!$E:$E,E$4,請求詳細!$F:$F,$A17) -> 0 | F17: =COUNTIFS(請求詳細!$E:$E,F$4,請求詳細!$F:$F,$A17) -> 0 | G17: =COUNTIFS(請求詳細!$E:$E,G$4,請求詳細!$F:$F,$A17) -> 0 | H17: =COUNTIF(請求詳細!$F:$F,$A17) -> 0 | I17: 2450 | J17: =H17*I17 -> 0 | K17: =SUM(D17:G17)-H17 -> 0
A18: R0232 | B18: 訪問看護ステーション （ラポール）男性 | C18: 4 | D18: =COUNTIFS(請求詳細!$E:$E,D$4,請求詳細!$F:$F,$A18) -> 0 | E18: =COUNTIFS(請求詳細!$E:$E,E$4,請求詳細!$F:$F,$A18) -> 0 | F18: =COUNTIFS(請求詳細!$E:$E,F$4,請求詳細!$F:$F,$A18) -> 0 | G18: =COUNTIFS(請求詳細!$E:$E,G$4,請求詳細!$F:$F,$A18) -> 0 | H18: =COUNTIF(請求詳細!$F:$F,$A18) -> 0 | I18: 2200 | J18: =H18*I18 -> 0 | K18: =SUM(D18:G18)-H18 -> 0
A19: R0233 | B19: 訪問看護ステーション （ラポール）男性 | C19: 2 | D19: =COUNTIFS(請求詳細!$E:$E,D$4,請求詳細!$F:$F,$A19) -> 0 | E19: =COUNTIFS(請求詳細!$E:$E,E$4,請求詳細!$F:$F,$A19) -> 0 | F19: =COUNTIFS(請求詳細!$E:$E,F$4,請求詳細!$F:$F,$A19) -> 0 | G19: =COUNTIFS(請求詳細!$E:$E,G$4,請求詳細!$F:$F,$A19) -> 0 | H19: =COUNTIF(請求詳細!$F:$F,$A19) -> 0 | I19: 1600 | J19: =H19*I19 -> 0 | K19: =SUM(D19:G19)-H19 -> 0
A20: R0241 | B20: その他 （生活・清掃）男女 | C20: 5 | D20: =COUNTIFS(請求詳細!$E:$E,D$4,請求詳細!$F:$F,$A20) -> 0 | E20: =COUNTIFS(請求詳細!$E:$E,E$4,請求詳細!$F:$F,$A20) -> 1 | F20: =COUNTIFS(請求詳細!$E:$E,F$4,請求詳細!$F:$F,$A20) -> 0 | G20: =COUNTIFS(請求詳細!$E:$E,G$4,請求詳細!$F:$F,$A20) -> 0 | H20: =COUNTIF(請求詳細!$F:$F,$A20) -> 1 | I20: 2330 | J20: =H20*I20 -> 2330 | K20: =SUM(D20:G20)-H20 -> 0
A21: R0242 | B21: その他 （生活・清掃）男女 | C21: 4 | D21: =COUNTIFS(請求詳細!$E:$E,D$4,請求詳細!$F:$F,$A21) -> 0 | E21: =COUNTIFS(請求詳細!$E:$E,E$4,請求詳細!$F:$F,$A21) -> 2 | F21: =COUNTIFS(請求詳細!$E:$E,F$4,請求詳細!$F:$F,$A21) -> 2 | G21: =COUNTIFS(請求詳細!$E:$E,G$4,請求詳細!$F:$F,$A21) -> 8 | H21: =COUNTIF(請求詳細!$F:$F,$A21) -> 12 | I21: 2110 | J21: =H21*I21 -> 25320 | K21: =SUM(D21:G21)-H21 -> 0
A22: R0243 | B22: その他 （生活・清掃）男女 | C22: 3 | D22: =COUNTIFS(請求詳細!$E:$E,D$4,請求詳細!$F:$F,$A22) -> 0 | E22: =COUNTIFS(請求詳細!$E:$E,E$4,請求詳細!$F:$F,$A22) -> 0 | F22: =COUNTIFS(請求詳細!$E:$E,F$4,請求詳細!$F:$F,$A22) -> 0 | G22: =COUNTIFS(請求詳細!$E:$E,G$4,請求詳細!$F:$F,$A22) -> 0 | H22: =COUNTIF(請求詳細!$F:$F,$A22) -> 0 | I22: 2200 | J22: =H22*I22 -> 0 | K22: =SUM(D22:G22)-H22 -> 0
A23: R0244 | B23: その他 （生活・清掃）男女 | C23: 2 | D23: =COUNTIFS(請求詳細!$E:$E,D$4,請求詳細!$F:$F,$A23) -> 0 | E23: =COUNTIFS(請求詳細!$E:$E,E$4,請求詳細!$F:$F,$A23) -> 0 | F23: =COUNTIFS(請求詳細!$E:$E,F$4,請求詳細!$F:$F,$A23) -> 0 | G23: =COUNTIFS(請求詳細!$E:$E,G$4,請求詳細!$F:$F,$A23) -> 0 | H23: =COUNTIF(請求詳細!$F:$F,$A23) -> 0 | I23: 1670 | J23: =H23*I23 -> 0 | K23: =SUM(D23:G23)-H23 -> 0
A24: R0251 | B24: 事務部 女性 | C24: 5 | D24: =COUNTIFS(請求詳細!$E:$E,D$4,請求詳細!$F:$F,$A24) -> 5 | E24: =COUNTIFS(請求詳細!$E:$E,E$4,請求詳細!$F:$F,$A24) -> 0 | F24: =COUNTIFS(請求詳細!$E:$E,F$4,請求詳細!$F:$F,$A24) -> 0 | G24: =COUNTIFS(請求詳細!$E:$E,G$4,請求詳細!$F:$F,$A24) -> 0 | H24: =COUNTIF(請求詳細!$F:$F,$A24) -> 5 | I24: 1640 | J24: =H24*I24 -> 8200 | K24: =SUM(D24:G24)-H24 -> 0
A25: R0252 | B25: 事務部 女性 | C25: 4 | D25: =COUNTIFS(請求詳細!$E:$E,D$4,請求詳細!$F:$F,$A25) -> 2 | E25: =COUNTIFS(請求詳細!$E:$E,E$4,請求詳細!$F:$F,$A25) -> 0 | F25: =COUNTIFS(請求詳細!$E:$E,F$4,請求詳細!$F:$F,$A25) -> 0 | G25: =COUNTIFS(請求詳細!$E:$E,G$4,請求詳細!$F:$F,$A25) -> 0 | H25: =COUNTIF(請求詳細!$F:$F,$A25) -> 2 | I25: 1320 | J25: =H25*I25 -> 2640 | K25: =SUM(D25:G25)-H25 -> 0
D26: =SUM(D5:D25) -> 18 | E26: =SUM(E5:E25) -> 23 | F26: =SUM(F5:F25) -> 16 | G26: =SUM(G5:G25) -> 54 | H26: =SUM(H5:H25) -> 106 | J26: =SUM(J5:J25) -> 238240
B28: ※R0222永田明日香様分5ヵ月分過剰請求の為2月分で調整しております。

Sheet 請求詳細
A1: 日付 | C1: 番号 | D1: 職種 | E1: 所属 | F1: 契約名 | G1: 氏名 | H1: 上衣品番 | I1: 色番 | J1: サイズ | K1: 枚数 | L1: 上衣品番 | M1: 色番 | N1: サイズ | O1: 枚数 | P1: 下衣品番 | Q1: サイズ | R1: 股下 | S1: 枚数
A2: 45778 | B2: 異動 | C2: 1 | D2: ヘルパーＳＴ | E2: ケアホーム | F2: R0201 | G2: 今田 寛人 | H2: UZL3073-2 | J2: EL | K2: 5 | P2: UZL2013-5 | Q2: LL | R2: 79 | S2: 5
C3: 2 | D3: ヘルパーＳＴ | E3: ケアホーム | F3: R0201 | G3: 黒田 晋平 | H3: UZL3073-2 | J3: LL | K3: 5 | P3: UZL2013-5 | Q3: L | R3: 82 | S3: 5
C4: 3 | D4: ヘルパーＳＴ | E4: ケアホーム | F4: R0201 | G4: 木寺 千鶴 | H4: UZL3073-2 | J4: S | K4: 5 | P4: UZL2013-5 | Q4: M | R4: 72 | S4: 5
C5: 4 | D5: ヘルパーＳＴ | E5: ケアホーム | F5: R0201 | G5: 黒澤 美佐枝 | H5: UZL3073-2 | J5: LL | K5: 5 | P5: UZL2013-5 | Q5: L | R5: 75 | S5: 5
C6: 5 | D6: ヘルパーＳＴ | E6: ケアホーム | F6: R0201 | G6: 橋爪 奈未 | H6: UZL3073-2 | J6: M | K6: 5 | P6: UZL2013-5 | Q6: S | R6: 75 | S6: 5
C7: 6 | D7: ヘルパーＳＴ | E7: ケアホーム | F7: R0201 | G7: 行本 喜代子 | H7: UZL3073-2 | J7: S | K7: 5 | P7: UZL2013-5 | Q7: SS | R7: 71 | S7: 5
C8: 7 | D8: ヘルパーＳＴ | E8: ケアホーム | F8: R0202 | G8: 平田 紀代美 | H8: UZL3073-2 | J8: S | K8: 4 | P8: UZL2013-5 | Q8: M | R8: 73 | S8: 4
C9: 8 | D9: ﾍﾙﾊﾟｰｽﾃｰｼｮﾝサービス提供責任者 | E9: ケアホーム | F9: R0211 | G9: 坂本 祐美子 | H9: UZL3207-3 | J9: LL | K9: 5 | P9: UZL2013-5 | Q9: L | R9: 64 | S9: 5
C10: 9 | D10: ﾍﾙﾊﾟｰｽﾃｰｼｮﾝサービス提供責任者 | E10: ケアホーム | F10: R0211 | G10: 古市 志郎 | H10: UZL3207-3 | J10: L | K10: 5 | P10: UZL2013-5 | Q10: L | R10: 73 | S10: 5
C11: 10 | D11: ラポール | E11: ケアホーム | F11: R0221 | G11: 林 恵子 | L11: RF5192 | M11: ﾈｲﾋﾞｰ×ﾀｰｺｲｽﾞ | N11: S | O11: 5 | P11: UZL2041-5 | Q11: S | R11: 67 | S11: 5
C12: 11 | D12: ラポール | E12: ケアホーム | F12: R0221 | G12: 西井 節子 | L12: RF5192 | M12: ﾈｲﾋﾞｰ×ﾀｰｺｲｽﾞ | N12: LL | O12: 5 | P12: UZL2041-5 | Q12: M | R12: 68 | S12: 5
A13: 45778 | B13: 異動 | C13: 12 | D13: ラポール | E13: ケアホーム | F13: R0221 | G13: 齊土 とし枝 | L13: RF5192 | M13: ﾈｲﾋﾞｰ×ﾀｰｺｲｽﾞ | N13: EL | O13: 5 | P13: UZL2041-5 | Q13: L | R13: 75 | S13: 5
C14: 13 | D14: ラポール | E14: ケアホーム | F14: R0221 | G14: 山下 郁代 | H14: RF5192 | I14: ﾀｰｺｲｽﾞ×ﾈｲﾋﾞｰ | J14: LL | K14: 2 | L14: RF5192 | M14: ﾈｲﾋﾞｰ×ﾀｰｺｲｽﾞ | N14: LL | O14: 3 | P14: UZL2041-5 | Q14: LL | R14: 71 | S14: 5
A15: 45777 | B15: 退職 | C15: 14 | D15: ラポール | E15: ケアホーム | G15: 加茂前 利恵
C16: 15 | D16: ラポール | E16: ケアホーム | F16: R0222 | G16: 是枝 哲子 | H16: RF5192 | I16: ﾀｰｺｲｽﾞ×ﾈｲﾋﾞｰ | J16: EL | K16: 2 | L16: RF5192 | M16: ﾈｲﾋﾞｰ×ﾀｰｺｲｽﾞ | N16: EL | O16: 2 | P16: UZL2041-5 | Q16: L | R16: 77 | S16: 4
C17: 16 | D17: ラポール | E17: ケアホーム | F17: R0222 | G17: 小山 ひとみ | H17: RF5192 | I17: ﾀｰｺｲｽﾞ×ﾈｲﾋﾞｰ | J17: L | K17: 2 | L17: RF5192 | M17: ﾈｲﾋﾞｰ×ﾀｰｺｲｽﾞ | N17: L | O17: 2 | P17: UZL2041-5 | Q17: M | R17: 67 | S17: 4
A18: 45770 | B18: 変更 | C18: 17 | D18: ラポール | E18: ケアホーム | F18: R0221 | G18: 岩 英子 | H18: RF5192 | I18: ﾀｰｺｲｽﾞ×ﾈｲﾋﾞｰ | J18: LL | K18: 2 | L18: RF5192 | M18: ﾈｲﾋﾞｰ×ﾀｰｺｲｽﾞ | N18: LL | O18: 3 | P18: UZL2041-5 | Q18: M | R18: 66 | S18: 5
C19: 18 | D19: ラポール | E19: ケアホーム | F19: R0222 | G19: 垣花 仁美 | H19: RF5192 | I19: ﾀｰｺｲｽﾞ×ﾈｲﾋﾞｰ | J19: S | K19: 2 | L19: RF5192 | M19: ﾈｲﾋﾞｰ×ﾀｰｺｲｽﾞ | N19: S | O19: 2 | P19: UZL2041-5 | Q19: S | R19: 68 | S19: 4
A20: 45839 | B20: 異動 | C20: 19 | D20: ラポール | E20: ケアホーム | F20: R0221 | G20: 天野 久美子 | L20: RF5192 | M20: ﾈｲﾋﾞｰ×ﾀｰｺｲｽﾞ | N20: S | O20: 5 | P20: UZL2041-5 | Q20: M | R20: 72 | S20: 5
A21: 45839 | B21: 異動 | C21: 20 | D21: ラポール | E21: ケアホーム | F21: R0224 | G21: 平賀 千瑞子 | L21: RF5192 | M21: ﾈｲﾋﾞｰ×ﾀｰｺｲｽﾞ | N21: LL | O21: 2 | P21: UZL2041-5 | Q21: L | R21: 73 | S21: 2
A22: 45854 | B22: 異動 | C22: 21 | D22: ラポール | E22: ケアホーム | F22: R0221 | G22: 中谷 彩 | H22: RF5192 | I22: ﾀｰｺｲｽﾞ×ﾈｲﾋﾞｰ | J22: LL | K22: 3 | L22: RF5192 | M22: ﾈｲﾋﾞｰ×ﾀｰｺｲｽﾞ | N22: LL | O22: 2 | P22: UZL2041-5 | Q22: LL | R22: 71 | S22: 5
A23: 45930 | B23: 退職 | C23: 22 | D23: ヘルパーＳＴ | E23: ケアホーム | G23: 森 享子
C24: 23 | D24: ヘルパーＳＴ | E24: ケアホームⅡ | F24: R0201 | G24: 山城 光司 | H24: UZL3073-2 | J24: EL | K24: 5 | P24: UZL2013-5 | Q24: LL | R24: 73 | S24: 5
C25: 24 | D25: ヘルパーＳＴ | E25: ケアホームⅡ | F25: R0201 | G25: 原田 友紀 | H25: UZL3073-2 | J25: LL | K25: 5 | P25: UZL2013-5 | Q25: L | R25: 72 | S25: 5
C26: 25 | D26: ヘルパーＳＴ | E26: ケアホームⅡ | F26: R0201 | G26: 松村 泰子 | H26: UZL3073-2 | J26: L | K26: 5 | P26: UZL2013-5 | Q26: M | R26: 71 | S26: 5
A27: 45961 | B27: 退職 | C27: 26 | D27: ヘルパーＳＴ | E27: ケアホームⅡ | G27: 池﨑 万理子
C28: 27 | D28: ヘルパーＳＴ | E28: ケアホームⅡ | F28: R0201 | G28: 谷川 尚美 | H28: UZL3073-2 | J28: L | K28: 5 | P28: UZL2013-5 | Q28: M | R28: 76 | S28: 5
C29: 28 | D29: ヘルパーＳＴ | E29: ケアホームⅡ | F29: R0201 | G29: 浅野 惠理子 | H29: UZL3073-2 | J29: S | K29: 5 | P29: UZL2013-5 | Q29: SS | R29: 72 | S29: 5
C30: 29 | D30: ヘルパーＳＴ | E30: ケアホームⅡ | F30: R0201 | G30: 市丸 眞理 | H30: UZL3073-2 | J30: EL | K30: 5 | P30: UZL2013-5 | Q30: L | R30: 70 | S30: 5
C31: 30 | D31: ヘルパーＳＴ | E31: ケアホームⅡ | F31: R0201 | G31: 安田 千景 | H31: UZL3073-2 | J31: LL | K31: 5 | P31: UZL2013-5 | Q31: L | R31: 73 | S31: 5
C32: 31 | D32: ヘルパーＳＴ | E32: ケアホームⅡ | F32: R0201 | G32: 松下 瑠美 | H32: UZL3073-2 | J32: M | K32: 5 | P32: UZL2013-5 | Q32: M | R32: 65 | S32: 5
A33: 45931 | B33: 入職 | C33: 32 | D33: ヘルパーＳＴ | E33: ケアホームⅡ | F33: R0202 | G33: 中野 優子 | H33: UZL3073-2 | J33: L | K33: 4 | P33: UZL2013-5 | Q33: M | R33: 71.5 | S33: 4
A34: 45778 | B34: 追加 | C34: 33 | D34: ヘルパーＳＴ | E34: ケアホームⅡ | F34: R0201 | G34: 砂川 幾子 | H34: UZL3073-2 | J34: L | K34: 5 | P34: UZL2013-5 | Q34: L | R34: 70.5 | S34: 5
C35: 34 | D35: ﾍﾙﾊﾟｰｽﾃｰｼｮﾝサービス提供責任者 | E35: ケアホームⅡ | F35: R0211 | G35: 松尾 久美子 | H35: UZL3207-3 | J35: L | K35: 5 | P35: UZL2013-5 | Q35: M | R35: 71 | S35: 5
C36: 35 | D36: ﾍﾙﾊﾟｰｽﾃｰｼｮﾝサービス提供責任者 | E36: ケアホームⅡ | F36: R0211 | G36: 伊庭 美佳子 | H36: UZL3207-3 | J36: L | K36: 5 | P36: UZL2013-5 | Q36: M | R36: 76 | S36: 5
C37: 36 | D37: ﾍﾙﾊﾟｰｽﾃｰｼｮﾝサービス提供責任者 | E37: ケアホームⅡ | F37: R0211 | G37: 吉田 美保 | H37: UZL3207-3 | J37: LL | K37: 5 | P37: UZL2013-5 | Q37: L | R37: 72 | S37: 5
C38: 37 | D38: ﾍﾙﾊﾟｰｽﾃｰｼｮﾝサービス提供責任者 | E38: ケアホームⅡ | F38: R0211 | G38: 加賀山 華恵 | H38: UZL3207-3 | J38: SS | K38: 5 | P38: UZL2013-5 | Q38: SS | R38: 74 | S38: 5
A39: 45825 | B39: 産休 | C39: 38 | D39: ラポール | E39: ケアホームⅡ | G39: 立野 彩名
C40: 39
...
