Workbook

Sheet 請求明細
A1: こやまクリニック ユニフォーム請求対象人数
B3: 2026年 | C3: 5 | E3: 月分
A5: 契約名 | B5: 職種 | C5: 貸与セット 枚数 | D5: 勤務体制 | E5: 月額単価/1人 | F5: 対象予定人数 | G5: 金額
A6: R0101 | B6: 医師（男女） | C6: 5 | D6: 常勤 | E6: 2350 | F6: =COUNTIF('個人明細 入力用'!H:H,A6) -> 3 | G6: =E6*F6 -> 7050
A7: R0102 | B7: 医師（男女） | C7: 3 | D7: 非常勤 | E7: 2250 | F7: =COUNTIF('個人明細 入力用'!H:H,A7) -> 1 | G7: =E7*F7 -> 2250
A8: R0103 | B8: 医師（男性白衣のみ） | C8: 5 | D8: 常勤 | E8: 1550 | F8: =COUNTIF('個人明細 入力用'!H:H,A8) -> 1 | G8: =E8*F8 -> 1550
A9: R0104 | B9: 医師（男性白衣のみ） | C9: 3 | D9: 非常勤 | E9: 930 | F9: =COUNTIF('個人明細 入力用'!H:H,A9) -> 0 | G9: =E9*F9 -> 0
A10: R0105 | B10: 医師（女性白衣のみ） | C10: 5 | D10: 常勤 | E10: 1500 | F10: =COUNTIF('個人明細 入力用'!H:H,A10) -> 0 | G10: =E10*F10 -> 0
A11: R0106 | B11: 医師（女性白衣のみ） | C11: 3 | D11: 非常勤 | E11: 1140 | F11: =COUNTIF('個人明細 入力用'!H:H,A11) -> 0 | G11: =E11*F11 -> 0
A12: R0107 | B12: 医師（男性白衣のみ） | C12: 4 | E12: 1310 | F12: =COUNTIF('個人明細 入力用'!H:H,A12) -> 0 | G12: =E12*F12 -> 0
A13: R0108 | B13: 医師（女性白衣のみ） | C13: 4 | E13: 1300 | F13: =COUNTIF('個人明細 入力用'!H:H,A13) -> 0 | G13: =E13*F13 -> 0
A14: R0109 | B14: 医師（男女） | C14: 4 | E14: 2250 | F14: =COUNTIF('個人明細 入力用'!H:H,A14) -> 0 | G14: =E14*F14 -> 0
A15: R0111 | B15: 看護師（女性） | C15: 5 | D15: 常勤 | E15: 2170 | F15: =COUNTIF('個人明細 入力用'!H:H,A15) -> 21 | G15: =E15*F15 -> 45570
A16: R0112 | B16: 看護師（女性） | C16: 4 | D16: 非常勤 | E16: 2060 | F16: =COUNTIF('個人明細 入力用'!H:H,A16) -> 5 | G16: =E16*F16 -> 10300
A17: R0113 | B17: 看護師（女性） | C17: 3 | D17: 非常勤 | E17: 1980 | F17: =COUNTIF('個人明細 入力用'!H:H,A17) -> 1 | G17: =E17*F17 -> 1980
A18: R0121 | B18: 眼科（女性） | C18: 5 | D18: 常勤 | E18: 2000 | F18: =COUNTIF('個人明細 入力用'!H:H,A18) -> 3 | G18: =E18*F18 -> 6000
A19: R0122 | B19: 眼科（女性） | C19: 4 | D19: 非常勤 | E19: 1890 | F19: =COUNTIF('個人明細 入力用'!H:H,A19) -> 2 | G19: =E19*F19 -> 3780
A20: R0131 | B20: 検査（女性） | C20: 5 | D20: 常勤 | E20: 2090 | F20: =COUNTIF('個人明細 入力用'!H:H,A20) -> 7 | G20: =E20*F20 -> 14630
A21: R0132 | B21: 検査（女性） | C21: 4 | D21: 非常勤 | E21: 1890 | F21: =COUNTIF('個人明細 入力用'!H:H,A21) -> 2 | G21: =E21*F21 -> 3780
A22: R0141 | B22: 画像技術科（女性） | C22: 5 | D22: 常勤 | E22: 2080 | F22: =COUNTIF('個人明細 入力用'!H:H,A22) -> 3 | G22: =E22*F22 -> 6240
A23: R0142 | B23: 画像技術科（男性） | C23: 5 | D23: 常勤 | E23: 2080 | F23: =COUNTIF('個人明細 入力用'!H:H,A23) -> 1 | G23: =E23*F23 -> 2080
A24: R0143 | B24: 画像技術科（女性） | C24: 4 | D24: 非常勤 | E24: 1890 | F24: =COUNTIF('個人明細 入力用'!H:H,A24) -> 0 | G24: =E24*F24 -> 0
A25: R0144 | B25: 画像技術科（男性） | C25: 4 | D25: 非常勤 | E25: 1890 | F25: =COUNTIF('個人明細 入力用'!H:H,A25) -> 0 | G25: =E25*F25 -> 0
A26: R0151 | B26: 理学療法士（女性） | C26: 5 | D26: 常勤 | E26: 2040 | F26: =COUNTIF('個人明細 入力用'!H:H,A26) -> 1 | G26: =E26*F26 -> 2040
... A46: R0232 | B46: 薬剤科（男性） | C46: 4 | D46: 非常勤 | E46: 1190 | F46: =COUNTIF('個人明細 入力用'!H:H,A46) -> 0 | G46: =E46*F46 -> 0
A47: R0241 | B47: 医師（男性ブレザーのみ） | C47: 5 | E47: 1820 | F47: =COUNTIF('個人明細 入力用'!H:H,A47) -> 0 | G47: =E47*F47 -> 0
A48: R0242 | B48: 医師（男性ブレザーのみ） | C48: 4 | E48: 1600 | F48: =COUNTIF('個人明細 入力用'!H:H,A48) -> 2 | G48: =E48*F48 -> 3200
E49: 合計 | F49: =SUM(F6:F48) -> 116 | G49: =SUM(G6:G48) -> 249420

Sheet 個人明細　入力用
C1: 氏名 | D1: ﾌﾘｶﾞﾅ | E1: 所属名 | F1: 職種 | G1: セット数 | H1: 契約番号
F3: 医師 | I3: 診察衣 | J3: サイズ | K3: 枚数 | L3: 上衣 | M3: サイズ | N3: 枚数 | O3: 上衣 | P3: サイズ | Q3: 枚数 | R3: パンツ | S3: サイズ | T3: 枚数 | U3: 股下
C4: 多田 惇 | D4: ﾀﾀﾞ ｼﾞｭﾝ | E4: 医師 | F4: 医師 | G4: 5 | H4: R0101 | I4: KEX5110 | J4: M | K4: 5 | L4: AY5522（ネイビー） | M4: M | N4: 5 | O4: LX5527（ホワイト） | R4: 257-28 | S4: M | T4: 5 | U4: 70
A5: 45838 | B5: 退職 | C5: 柏木 孝夫 | D5: ｶｼﾜｷﾞﾀｶｵ | E5: 医師 | F5: 医師
A6: 45870 | B6: 変更 | C6: 宮本 翔斗 | D6: ﾐﾔﾓﾄ ｼｮｳﾄ | E6: 医師 | F6: 医師 | G6: 4（ﾌﾞﾚｻﾞｰのみ） | H6: R0242 | L6: KES5160（ホワイト） | M6: L | N6: 4
C7: 華山 博美 | D7: ﾊﾅﾔﾏ ﾋﾛﾐ | E7: 医師 | F7: 医師 | G7: 5 | H7: R0101 | I7: HK13 | J7: L | K7: 1 | L7: AY5522（ネイビー） | M7: L | N7: 5 | O7: LX5527（ホワイト） | R7: 163-28 | S7: L | T7: 5 | U7: 74
C8: 小山 治 | D8: ｺﾔﾏ ｵｻﾑ | E8: 医師 | F8: 医師 | G8: 5 | H8: R0101 | I8: KEX5110 | J8: L | K8: 5 | L8: AY5522（ネイビー） | M8: L | N8: 3 | O8: LX5527（ホワイト） | P8: L | Q8: 2 | R8: 257-28 | S8: L | T8: 5 | U8: 70
A9: 46049 | B9: 退職 | C9: 石川 弓子 | D9: ｲｼｶﾜ ﾕﾐｺ | E9: 医師 | F9: 医師
A10: 45861 | B10: 退職 | C10: 倉田 雅之 | D10: ｸﾗﾀ ﾏｻﾕｷ | E10: 医師 | F10: 医師
C11: 大路 剛 | D11: ｵｵｼﾞ ｺﾞｳ | E11: 医師 | F11: 医師 | G11: 3 | H11: R0102 | I11: KEX5110 | J11: Ｌ | K11: 3 | L11: AY5522（ネイビー） | M11: L | N11: 3 | O11: LX5527（ホワイト） | R11: 257-28 | S11: M | T11: 3 | U11: 73
A12: 46112 | B12: 退職 | C12: 谷口 茉莉佳 | D12: ﾀﾆｸﾞﾁ ﾏﾘｶ | E12: 医師 | F12: 医師
A13: 45765 | B13: 追加 | C13: 内橋 猛 | D13: ｳﾁﾊｼ ﾀｹｼ | E13: 医師 | F13: 医師 | G13: 5（白衣のみ） | H13: R0103 | I13: KEX5110 | J13: L | K13: 4
C14: 西谷 裕美子 | E14: 医師 | F14: 医師 | G14: 3月退職
A15: 46113 | B15: 入職 | C15: 楠 直弥 | D15: ｸｽﾉｷ ﾅｵﾔ | E15: 医師 | F15: 医師 | G15: 4（ﾌﾞﾚｻﾞｰのみ） | H15: R0242 | L15: KES5160（ホワイト） | M15: L | N15: 4
F17: 看護師 | I17: 上衣 | J17: サイズ | K17: 枚数 | L17: 上衣 | M17: サイズ | N17: 枚数 | O17: パンツ | P17: サイズ | Q17: 枚数 | R17: 股下 | S17: パンツ | T17: サイズ | U17: 枚数 | V17: 股下
C18: 髙木 光 | D18: ﾀｶｷﾞ ﾋｶﾙ | E18: 看護科 | F18: 看護師 | G18: 5 | H18: R0111 | I18: LX4157(ﾎﾜｲﾄ) | J18: LL | K18: 2 | L18: RF5482(ﾈｲﾋﾞｰ) | M18: LL | N18: 3 | O18: NI5233(ﾎﾜｲﾄ) | P18: L | Q18: 2 | R18: 67 | S18: RF5503(ﾈｲﾋﾞｰ) | T18: L | U18: 3 | V18: 67
C19: 中山 久美 | D19: ﾅｶﾔﾏ ﾋｻﾐ | E19: 看護科 | F19: 看護師 | G19: 5 | H19: R0111 | I19: LX4157(ﾎﾜｲﾄ) | J19: S | K19: 3 | L19: RF5482(ﾈｲﾋﾞｰ) | M19: S | N19: 2 | O19: NI5233(ﾎﾜｲﾄ) | P19: SS | Q19: 3 | R19: 70 | S19: RF5503(ﾈｲﾋﾞｰ) | T19: SS | U19: 2 | V19: 70
C20: 横野 和江 | D20: ﾖｺﾉ ｶｽﾞｴ | E20: 看護科 | F20: 看護師 | G20: 5 | H20: R0111 | I20: LX4157(ﾎﾜｲﾄ) | J20: LL | K20: 2 | L20: RF5482(ﾈｲﾋﾞｰ) | M20: LL | N20: 3 | O20: NI5233(ﾎﾜｲﾄ) | P20: L | Q20: 2 | R20: 68 | S20: RF5503(ﾈｲﾋﾞｰ) | T20: L | U20: 3 | V20: 68
C21: 紺原 美幸 | D21: ｺﾝﾊﾞﾗ ﾐﾕｷ | E21: 看護科 | F21: 看護師 | G21: 5 | H21: R0111 | I21: LX4157(ﾎﾜｲﾄ) | J21: M | K21: 2 | L21: RF5482(ﾈｲﾋﾞｰ) | M21: M | N21: 3 | O21: NI5233(ﾎﾜｲﾄ) | P21: M | Q21: 2 | R21: 70 | S21: RF5503(ﾈｲﾋﾞｰ) | T21: M | U21: 3 | V21: 70
C22: 有吉 智美 | D22: ｱﾘﾖｼ ﾄﾓﾐ | E22: 看護科 | F22: 看護師 | G22: 5 | H22: R0111 | I22: LX4157(ﾎﾜｲﾄ) | J22: S | K22: 2 | L22: RF5482(ﾈｲﾋﾞｰ) | M22: S | N22: 3 | O22: NI5233(ﾎﾜｲﾄ) | S22: RF5503(ﾈｲﾋﾞｰ) | T22: SS | U22: 5 | V22: 70
C23: 三枝 陽子 | D23: ﾐｴ ﾖｳｺ | E23: 看護科 | F23: 看護師 | G23: 5 | H23: R0111 | I23: LX4157(ﾎﾜｲﾄ) | J23: M | K23: 2 | L23: RF5482(ﾈｲﾋﾞｰ) | M23: M | N23: 3 | O23: NI5233(ﾎﾜｲﾄ) | S23: RF5503(ﾈｲﾋﾞｰ) | T23: M | U23: 5 | V23: 72
C24: 松本 ひろみ | D24: ﾏﾂﾓﾄ ﾋﾛﾐ | E24: 看護科 | F24: 看護師 | G24: 5 | H24: R0111 | I24: LX4157(ﾎﾜｲﾄ) | J24: LL | K24: 2 | L24: RF5482(ﾈｲﾋﾞｰ) | M24: LL | N24: 3 | O24: NI5233(ﾎﾜｲﾄ) | P24: L | Q24: 2 | R24: 70 | S24: RF5503(ﾈｲﾋﾞｰ) | T24: L | U24: 3 | V24: 70
C25: 北林 寛子 | D25: ｷﾀﾊﾞﾔｼ ﾋﾛｺ | E25: 看護科 | F25: 看護師 | G25: 5 | H25: R0111 | I25: LX4157(ﾎﾜｲﾄ) | L25: RF5482(ﾈｲﾋﾞｰ) | M25: M | N25: 5 | O25: NI5233(ﾎﾜｲﾄ) | S25: RF5503(ﾈｲﾋﾞｰ) | T25: L | U25: 5 | V25: 67
C26: 志内 久美 | D26: ｼｳﾁ ｸﾐ | E26: 看護科 | F26: 看護師 | G26: 5 | H26: R0111 | I26: LX4157(ﾎﾜｲﾄ) | J26: M | K26: 2 | L26: RF5482(ﾈｲﾋﾞｰ) | M26: M | N26: 3 | O26: NI5233(ﾎﾜｲﾄ) | P26: S | Q26: 2 | R26: 72 | S26: RF5503(ﾈｲﾋﾞｰ) | T26: S | U26: 3 | V26: 72
C27: 田中 真由子 | D27: ﾀﾅｶ ﾏﾕｺ | E27: 看護科 | F27: 看護師 | G27: 5 | H27: R0111 | I27: LX4157(ﾎﾜｲﾄ) | J27: L | K27: 2 | L27: RF5482(ﾈｲﾋﾞｰ) | M27: L | N27: 3 | O27: NI5233(ﾎﾜｲﾄ) | P27: L | Q27: 1 | R27: 79 | S27: RF5503(ﾈｲﾋﾞｰ) | T27: L | U27: 4 | V27: 79
B28: 退職 | C28: 三木 里奈 | D28: ﾐｷ ﾘﾅ | E28: 看護科 | F28: 看護師 | I28: LX4157(ﾎﾜｲﾄ) | L28: RF5482(ﾈｲﾋﾞｰ) | O28: NI5233(ﾎﾜｲﾄ) | S28: RF5503(ﾈｲﾋﾞｰ)
C29: 福井 明日香 | D29: ﾌｸｲ ｱｽｶ | E29: 看護科 | F29: 看護師 | G29: 5 | H29: R0111 | I29: LX4157(ﾎﾜｲﾄ) | J29: S | K29: 2 | L29: RF5482(ﾈｲﾋﾞｰ) | M29: S | N29: 3 | O29: NI5233(ﾎﾜｲﾄ) | P29: S | Q29: 2 | R29: 69 | S29: RF5503(ﾈｲﾋﾞｰ) | T29: S | U29: 3 | V29: 69
C30: 高野 実佳 | D30: ﾀｶﾉ ﾐｶ | E30: 看護科 | F30: 看護師 | G30: 5 | H30: R0111 | I30: LX4157(ﾎﾜｲﾄ) | J30: EL | K30: 2 | L30: RF5482(ﾈｲﾋﾞｰ) | M30: EL | N30: 3 | O30: NI5233(ﾎﾜｲﾄ) | P30: LL | Q30: 3 | R30: 73 | S30: RF5503(ﾈｲﾋﾞｰ) | T30: LL | U30: 2 | V30: 73
C31: 村井 美奈子 | D31: ﾑﾗｲ ﾐﾅｺ | E31: 看護科 | F31: 看護師 | G31: 4 | H31: R0112 | I31: LX4157(ﾎﾜｲﾄ) | J31: LL | K31: 2 | L31: RF5482(ﾈｲﾋﾞｰ) | M31: LL | N31: 2 | O31: NI5233(ﾎﾜｲﾄ) | P31: L | Q31: 1 | R31: 76 | S31: RF5503(ﾈｲﾋﾞｰ) | T31: L | U31: 3 | V31: 76
C32: 岸本 信江 | D32: ｷｼﾓﾄ ﾉﾌﾞｴ | E32: 看護科 | F32: 看護師 | G32: 4 | H32: R0112 | I32: LX4157(ﾎﾜｲﾄ) | J32: M | K32: 2 | L32: RF5482(ﾈｲﾋﾞｰ) | M32: M | N32: 2 | O32: NI5233(ﾎﾜｲﾄ) | P32: M | Q32: 2 | R32: 73 | S32: RF5503(ﾈｲﾋﾞｰ) | T32: M | U32: 2 | V32: 73
C33: 佐藤 祐子 | D33: ｻﾄｳ ﾕｳｺ | E33: 看護科 | F33: 看護師 | G33: 5 | H33: R0111 | I33: LX4157(ﾎﾜｲﾄ) | J33: L | K33: 3 | L33: RF5482(ﾈｲﾋﾞｰ) | M33: L | N33: 2 | O33: NI5233(ﾎﾜｲﾄ) | P33: M | Q33: 2 | R33: 72 | S33: RF5503(ﾈｲﾋﾞｰ) | T33: M | U33: 3 | V33: 72
C34: 岩本 由佳子 | D34: ｲﾜﾓﾄ ﾕｶｺ | E34: 看護科 | F34: 看護師 | G34: 5 | H34: R0111 | I34: LX4157(ﾎﾜｲﾄ) | J34: LL | K34: 2 | L34: RF5482(ﾈｲﾋﾞｰ) | M34: LL | N34: 3 | O34: NI5233(ﾎﾜｲﾄ) | P34: L | Q34: 2 | R34: 68 | S34: RF5503(ﾈｲﾋﾞｰ) | T34: L | U34: 3 | V34: 68
C35: 加納 友子 | D35: ｶﾉｳ ﾄﾓｺ | E35: 看護科 | F35: 看護師 | G35: 5 | H35: R0111 | I35: LX4157(ﾎﾜｲﾄ) | J35: M | K35: 2 | L35: RF5482(ﾈｲﾋﾞｰ) | M35: M | N35: 3 | O35: NI5233(ﾎﾜｲﾄ) | P35: M | Q35: 2 | R35: 68 | S35: RF5503(ﾈｲﾋﾞｰ) | T35: M | U35: 3 | V35: 68
C36: 青木 美穂 | D36: ｱｵｷ ﾐﾎ | E36: 看護科 | F36: 看護師 | G36: 5 | H36: R0111 | I36: LX4157(ﾎﾜｲﾄ) | J36: M | K36: 3 | L36: RF5482(ﾈｲﾋﾞｰ) | M36: M | N36: 2 | O36: NI5233(ﾎﾜｲﾄ) | P36: M | Q36: 3 | R36: 68 | S36: RF5503(ﾈｲﾋﾞｰ) | T36: M | U36: 2 | V36: 68
C37: 入江 範子 | D37: ｲﾘｴ ﾉﾘｺ | E37: 看護科 | F37: 看護師 | G37: 5 | H37: R0111 | I37: LX4157(ﾎﾜｲﾄ) | J37: S | K37: 3 | L37: RF5482(ﾈｲﾋﾞｰ) | M37: S | N37: 2 | O37: NI5233(ﾎﾜｲﾄ) | P37: S | Q37: 3 | R37: 70 | S37: RF5503(ﾈｲﾋﾞｰ) | T37: S | U37: 2 | V37: 70
C38: 垣内 恵 | D38: ｶｷｳﾁ ﾒｸﾞﾐ | E38: 看護科 | F38: 看護師 | G38: 5 | H38: R0111 | I38: LX4157(ﾎﾜｲﾄ) | J38: M | K38: 2 | L38: RF5482(ﾈｲﾋﾞｰ) | M38: M | N38: 3 | O38: NI5233(ﾎﾜｲﾄ) | P38: SS | Q38: 2 | R38: 65 | S38: RF5503(ﾈｲﾋﾞｰ) | T38: SS | U38: 3 | V38: 65
A39: 45931 | B39: 変更 | C39: 川村 まどか | D39: ｶﾜﾑﾗ ﾏﾄﾞｶ | E39: 看護科 | F39: 看護師 | G39: 5 | H39: R0111 | I39: LX4157(ﾎﾜｲﾄ) | J39: M | K39: 1 | L39: RF5482(ﾈｲﾋﾞｰ) | M39: M | N39: 4 | O39: NI5233(ﾎﾜｲﾄ) | P39: S | Q39: 1 | R39: 77 | S39: RF5503(ﾈｲﾋﾞｰ) | T39: S | U39: 4 | V39: 77 | W39: 4枚→5枚
C40: 岡田 真理子 | D40: ｵｶﾀﾞ ﾏﾘｺ | E40: 看護科 | F40: 看護師 | G40: 4 | H40: R0112 | I40: LX4157(ﾎﾜｲﾄ) | J40: M | K40: 2 | L40: RF5482(ﾈｲﾋﾞｰ) | M40: M | N40: 2 | O40: NI5233(ﾎﾜｲﾄ) | P40: M | Q40: 2 | R40: 70 | S40: RF5503(ﾈｲﾋﾞｰ) | T40: M | U40: 2 | V40: 70
C41: 井野 一恵 | D41: ｲﾉ ｶｽﾞｴ | E41: 看護科 | F41: 看護師 | G41: 5 | H41: R0111 | I41: LX4157(ﾎﾜｲﾄ) | J41: LL | K41: 2 | L41: RF5482(ﾈｲﾋﾞｰ) | M41: LL | N41: 3 | O41: NI5233(ﾎﾜｲﾄ) | P41: L | Q41: 2 | R41: 67 | S41: RF5503(ﾈｲﾋﾞｰ) | T41: L | U41: 3 | V41: 67
C42: 福田 あゆ美 | D42: ﾌｸﾀﾞ ｱﾕﾐ | E42: 看護科 | F42: 看護師 | G42: 4 | H42: R0112 | I42: LX4157(ﾎﾜｲﾄ) | J42: L | K42: 2 | L42: RF5482(ﾈｲﾋﾞｰ) | M42: L | N42: 2 | O42: NI5233(ﾎﾜｲﾄ) | P42: L | Q42: 2 | R42: 75 | S42: RF5503(ﾈｲﾋﾞｰ) | T42: L | U42: 2 | V42: 75
...
